<?xml version="1.0" ?>
<!-- =================================================================================== -->
<!-- |    This document was autogenerated by xacro from ./x_allegro_right_curved.xacro | -->
<!-- |    EDITING THIS FILE BY HAND IS NOT RECOMMENDED                                 | -->
<!-- =================================================================================== -->
<robot name="allegro_hand_left">
  <!-- Rviz colors -->
  <material name="black">
    <color rgba="0.1 0.1 0.1 1.0"/>
  </material>
  <material name="blue">
    <color rgba="0.0 0.0 0.8 1.0"/>
  </material>
  <material name="green">
    <color rgba="0.0 0.8 0.0 1.0"/>
  </material>
  <material name="grey">
    <color rgba="0.2 0.2 0.2 1.0"/>
  </material>
  <material name="orange">
    <color rgba="1.0 0.4235294117647059 0.0392156862745098 1.0"/>
  </material>
  <material name="brown">
    <color rgba="0.8705882352941177 0.8117647058823529 0.7647058823529411 1.0"/>
  </material>
  <material name="red">
    <color rgba="0.8 0.0 0.0 1.0"/>
  </material>
  <material name="white">
    <color rgba="1.0 1.0 1.0 1.0"/>
  </material>
  <link name="world"/>
  <link name="hand_root">
    <origin xyz="0 0 0"/>
  </link>
  <joint name="root_to_base" type="fixed">
    <origin rpy="0 0 0" xyz="0 0 0"/>
    <parent link="world"/>
    <child link="hand_root"/>
  </joint>
  <link name="base_0_palm_link">
    <visual>
      <origin rpy="0 0 1.5707963267948966" xyz="0 0 0"/>
      <geometry>
        <mesh filename="package://xela_models/mesh/allegro/base_new_right.stl" scale="0.001 0.001 0.001"/>
      </geometry>
      <material name="cyan">
        <color rgba="0.0 1.0 1.0 1"/>
      </material>
    </visual>
    <collision>
      <origin rpy="0 0 0" xyz="-0.009300 0 -0.0475"/>
      <geometry>
        <box size="0.0408 0.1130 0.095"/>
      </geometry>
    </collision>
    <inertial>
      <mass value="0.4288"/>
      <origin rpy="0 0 0" xyz="0 0 0"/>
      <inertia ixx="2.04e-03" ixy="8.58e-06" ixz="8.58e-06" iyy="1.23e-03" iyz="0.0" izz="1.25e-03"/>
    </inertial>
  </link>
  <joint name="base_0_ahr_fixed" type="fixed">
    <origin rpy="0.0 0.0 0.0" xyz="0.0 0.0 0.0"/>
    <parent link="hand_root"/>
    <child link="base_0_palm_link"/>
  </joint>
  <joint name="base_x_taxel_0_16_4x6_fixed" type="fixed">
    <origin rpy="1.5707963267948966 3.141592653589793 1.5707963267948966" xyz="0.014 -0.021 -0.0204"/>
    <parent link="base_0_palm_link"/>
    <child link="base_x_taxel_0_16_4x6_link"/>
  </joint>
  <link name="base_x_taxel_0_16_4x6_link">
    <collision>
      <origin rpy="0 0 0" xyz="0 0 0"/>
      <geometry>
        <mesh filename="package://xela_models/mesh/uSPa46_2409.stl" scale="0.001 0.001 0.001"/>
      </geometry>
    </collision>
    <visual>
      <origin rpy="0 0 0" xyz="0 0 0"/>
      <geometry>
        <mesh filename="package://xela_models/mesh/uSPa46_2409.stl" scale="0.001 0.001 0.001"/>
      </geometry>
      <material name="red"/>
    </visual>
  </link>
  <gazebo reference="base_x_taxel_0_16_4x6_link">
    <material>Gazebo/Red</material>
  </gazebo>
  <joint name="base_x_taxel_0_17_4x6_fixed" type="fixed">
    <origin rpy="1.5707963267948966 0.0 1.5707963267948966" xyz="0.014 0.021 -0.0204"/>
    <parent link="base_0_palm_link"/>
    <child link="base_x_taxel_0_17_4x6_link"/>
  </joint>
  <link name="base_x_taxel_0_17_4x6_link">
    <collision>
      <origin rpy="0 0 0" xyz="0 0 0"/>
      <geometry>
        <mesh filename="package://xela_models/mesh/uSPa46_2409.stl" scale="0.001 0.001 0.001"/>
      </geometry>
    </collision>
    <visual>
      <origin rpy="0 0 0" xyz="0 0 0"/>
      <geometry>
        <mesh filename="package://xela_models/mesh/uSPa46_2409.stl" scale="0.001 0.001 0.001"/>
      </geometry>
      <material name="green"/>
    </visual>
  </link>
  <gazebo reference="base_x_taxel_0_17_4x6_link">
    <material>Gazebo/Red</material>
  </gazebo>
  <joint name="base_x_taxel_0_18_4x6_fixed" type="fixed">
    <origin rpy="1.5707963267948966 3.141592653589793 1.5707963267948966" xyz="0.014 -0.021 -0.0515"/>
    <parent link="base_0_palm_link"/>
    <child link="base_x_taxel_0_18_4x6_link"/>
  </joint>
  <link name="base_x_taxel_0_18_4x6_link">
    <collision>
      <origin rpy="0 0 0" xyz="0 0 0"/>
      <geometry>
        <mesh filename="package://xela_models/mesh/uSPa46_2409.stl" scale="0.001 0.001 0.001"/>
      </geometry>
    </collision>
    <visual>
      <origin rpy="0 0 0" xyz="0 0 0"/>
      <geometry>
        <mesh filename="package://xela_models/mesh/uSPa46_2409.stl" scale="0.001 0.001 0.001"/>
      </geometry>
      <material name="blue"/>
    </visual>
  </link>
  <gazebo reference="base_x_taxel_0_18_4x6_link">
    <material>Gazebo/Red</material>
  </gazebo>
  <link name="base_0_ah_link_00">
    <visual>
      <geometry>
        <mesh filename="package://xela_models/mesh/allegro/link_12.0_right.STL"/>
      </geometry>
      <material name="grey"/>
      <origin rpy="3.141592653589793 0 0" xyz="0 0 0"/>
    </visual>
    <collision>
      <geometry>
        <box size="0.0358 0.034 0.0455"/>
      </geometry>
      <origin rpy="0 0 0" xyz="-0.0179 0.009 0.0145"/>
    </collision>
    <inertial>
      <mass value="0.0176"/>
      <origin rpy="0 0 0" xyz="0 0 0"/>
      <inertia ixx="3.36e-06" ixy="0.0" ixz="1.76e-08" iyy="3.84e-06" iyz="2.46e-07" izz="2.59e-06"/>
    </inertial>
  </link>
  <joint name="ah_joint00" type="revolute">
    <axis xyz="-1 0 0"/>
    <limit effort="15" lower="0.263" upper="1.396" velocity="7"/>
    <parent link="base_0_palm_link"/>
    <child link="base_0_ah_link_00"/>
    <origin rpy="0 -1.6580627893946132 -1.5707963267948966" xyz="-0.0182 0.019333 -0.045987"/>
    <dynamics damping="3" friction="10"/>
  </joint>
  <link name="base_0_ah_link_01">
    <visual>
      <geometry>
        <mesh filename="package://xela_models/mesh/allegro/link_13.0.STL"/>
      </geometry>
      <material name="grey"/>
    </visual>
    <collision>
      <geometry>
        <box size="0.0196 0.0275 0.0177"/>
      </geometry>
      <origin rpy="0 0 0" xyz="0 0 0.00885"/>
    </collision>
    <inertial>
      <mass value="0.0127"/>
      <origin rpy="0 0 0" xyz="0 0 0"/>
      <inertia ixx="1.38e-07" ixy="1.27e-10" ixz="4.83e-09" iyy="6.83e-08" iyz="0.0" izz="1.16e-07"/>
    </inertial>
  </link>
  <link name="base_0_ah_link_02_cover">
    <visual>
      <geometry>
        <mesh filename="package://xela_models/mesh/allegro/thumb_1_cover.stl"/>
      </geometry>
      <material name="red"/>
    </visual>
    <collision>
      <geometry>
        <mesh filename="package://xela_models/mesh/allegro/thumb_1_cover.stl"/>
      </geometry>
      <origin rpy="0 0 0" xyz="0 0 0"/>
    </collision>
  </link>
  <joint name="base_0_ah_link_02_cover_joint" type="fixed">
    <origin rpy="0.0 0.0 0.0" xyz="0.0 0.0 0.0"/>
    <parent link="base_0_ah_link_02"/>
    <child link="base_0_ah_link_02_cover"/>
  </joint>
  <joint name="ah_joint01" type="revolute">
    <axis xyz="0 0 1"/>
    <limit effort="15" lower="-0.10499999999999998" upper="1.1629999999999998" velocity="7"/>
    <parent link="base_0_ah_link_00"/>
    <child link="base_0_ah_link_01"/>
    <origin xyz="-0.027 0.005 0.0399"/>
    <dynamics damping="3" friction="5"/>
  </joint>
  <link name="base_0_ah_link_02">
    <visual>
      <geometry>
        <mesh filename="package://xela_models/mesh/allegro/thumb_1.0.stl"/>
      </geometry>
      <material name="black"/>
    </visual>
    <collision>
      <geometry>
        <box size="0.0196 0.0275 0.0514"/>
      </geometry>
      <origin rpy="0 0 0" xyz="0 0 0.0257"/>
    </collision>
    <!--covers are always with sensors-->
    <inertial>
      <mass value="0.0457"/>
      <origin rpy="0 0 0" xyz="0 0 0"/>
      <inertia ixx="3.20e-06" ixy="9.14e-09" ixz="1.46e-07" iyy="3.03e-06" iyz="0.0" izz="1.47e-06"/>
    </inertial>
  </link>
  <link name="base_0_ah_link_03_cover">
    <visual>
      <geometry>
        <mesh filename="package://xela_models/mesh/allegro/thumb_2_cover.stl"/>
      </geometry>
      <material name="red"/>
    </visual>
    <collision>
      <geometry>
        <mesh filename="package://xela_models/mesh/allegro/thumb_2_cover.stl"/>
      </geometry>
      <origin rpy="0 0 0" xyz="0 0 0"/>
    </collision>
  </link>
  <joint name="base_0_ah_link_03_cover_joint" type="fixed">
    <origin rpy="0.0 0.0 0.0" xyz="0.0 0.0 0.0"/>
    <parent link="base_0_ah_link_03"/>
    <child link="base_0_ah_link_03_cover"/>
  </joint>
  <joint name="base_x_taxel_0_01_4x4_fixed" type="fixed">
    <origin rpy="0.0 1.5707963267948966 0.0" xyz="0.011 -0.012 0.023"/>
    <parent link="base_0_ah_link_02"/>
    <child link="base_x_taxel_0_01_4x4_link"/>
  </joint>
  <link name="base_x_taxel_0_01_4x4_link">
    <collision>
      <origin rpy="0 0 0" xyz="0 0 0"/>
      <geometry>
        <mesh filename="package://xela_models/mesh/4x4.stl"/>
      </geometry>
    </collision>
    <visual>
      <origin rpy="0 0 0" xyz="0 0 0"/>
      <geometry>
        <mesh filename="package://xela_models/mesh/4x4.stl"/>
      </geometry>
      <material name="blue"/>
    </visual>
  </link>
  <gazebo reference="base_x_taxel_0_01_4x4_link">
    <material>Gazebo/Green</material>
  </gazebo>
  <joint name="ah_joint02" type="revolute">
    <axis xyz="0 1 0"/>
    <limit effort="15" lower="-0.18899999999999997" upper="1.644" velocity="7"/>
    <parent link="base_0_ah_link_01"/>
    <child link="base_0_ah_link_02"/>
    <origin xyz="0 0 0.0177"/>
    <dynamics damping="3" friction="10"/>
  </joint>
  <link name="base_0_ah_link_03">
    <visual>
      <geometry>
        <mesh filename="package://xela_models/mesh/allegro/thumb_2.0.stl"/>
      </geometry>
      <material name="black"/>
    </visual>
    <collision>
      <geometry>
        <box size="0.0196 0.0275 0.042300000000000004"/>
      </geometry>
      <origin rpy="0 0 0" xyz="0 0 0.021150000000000002"/>
    </collision>
    <inertial>
      <mass value="0.0753"/>
      <origin rpy="0 0 0" xyz="0 0 0"/>
      <inertia ixx="2.90e-05" ixy="0.0" ixz="0.0" iyy="2.90e-05" iyz="0.0" izz="6.88e-06"/>
    </inertial>
  </link>
  <joint name="base_x_taxel_0_02_4x4_fixed" type="fixed">
    <origin rpy="0.0 1.5707963267948966 0.0" xyz="0.011 -0.012 0.021"/>
    <parent link="base_0_ah_link_03"/>
    <child link="base_x_taxel_0_02_4x4_link"/>
  </joint>
  <link name="base_x_taxel_0_02_4x4_link">
    <collision>
      <origin rpy="0 0 0" xyz="0 0 0"/>
      <geometry>
        <mesh filename="package://xela_models/mesh/4x4.stl"/>
      </geometry>
    </collision>
    <visual>
      <origin rpy="0 0 0" xyz="0 0 0"/>
      <geometry>
        <mesh filename="package://xela_models/mesh/4x4.stl"/>
      </geometry>
      <material name="blue"/>
    </visual>
  </link>
  <gazebo reference="base_x_taxel_0_02_4x4_link">
    <material>Gazebo/Green</material>
  </gazebo>
  <joint name="ah_joint03" type="revolute">
    <axis xyz="0 1 0"/>
    <limit effort="15" lower="-0.162" upper="1.7189999999999999" velocity="7"/>
    <parent link="base_0_ah_link_02"/>
    <child link="base_0_ah_link_03"/>
    <origin xyz="0 0 0.0514"/>
    <dynamics damping="3" friction="12"/>
  </joint>
  <joint name="base_x_taxel_0_03_aftc_fixed" type="fixed">
    <origin rpy="1.5707963267948966 0.0 1.5707963267948966" xyz="-0.013 0.0 0.0315"/>
    <parent link="base_0_ah_link_03"/>
    <child link="base_x_taxel_0_03_aftc_link"/>
  </joint>
  <link name="base_x_taxel_0_03_aftc_link">
    <collision>
      <origin rpy="0 0 0" xyz="0 0 0"/>
      <geometry>
        <mesh filename="package://xela_models/mesh/ft_c.stl"/>
      </geometry>
    </collision>
    <visual>
      <origin rpy="0 0 0" xyz="0 0 0"/>
      <geometry>
        <mesh filename="package://xela_models/mesh/ft_c.stl" scale="0.93 0.93 0.93"/>
      </geometry>
      <material name="green"/>
    </visual>
  </link>
  <link name="base_0_ah_link_10">
    <visual>
      <geometry>
        <mesh filename="package://xela_models/mesh/allegro/link_0.0_ext.STL"/>
      </geometry>
      <material name="grey"/>
    </visual>
    <collision>
      <geometry>
        <box size="0.0196 0.0275 0.0164"/>
      </geometry>
      <origin rpy="0 0 0" xyz="0 0 0.011200000000000002"/>
    </collision>
    <inertial>
      <mass value="0.0127"/>
      <origin rpy="0 0 0" xyz="0 0 0"/>
      <inertia ixx="1.38e-07" ixy="1.27e-10" ixz="4.83e-09" iyy="6.83e-08" iyz="0.0" izz="1.16e-07"/>
    </inertial>
  </link>
  <joint name="ah_joint10" type="revolute">
    <axis xyz="0 0 1"/>
    <limit effort="15" lower="-0.47" upper="0.47" velocity="7"/>
    <parent link="base_0_palm_link"/>
    <child link="base_0_ah_link_10"/>
    <origin rpy="-0.08726646259971647 0 0" xyz="0 0.0435 -0.001542"/>
  </joint>
  <link name="base_0_ah_link_11">
    <visual>
      <geometry>
        <mesh filename="package://xela_models/mesh/allegro/link_1.0.stl"/>
      </geometry>
      <material name="black"/>
    </visual>
    <collision>
      <geometry>
        <box size="0.0196 0.0275 0.054"/>
      </geometry>
      <origin rpy="0 0 0" xyz="0 0 0.027"/>
    </collision>
    <inertial>
      <mass value="0.0809"/>
      <origin rpy="0 0 0" xyz="0 0 0"/>
      <inertia ixx="1.75e-05" ixy="0.0" ixz="5.66e-08" iyy="1.80e-05" iyz="0.0" izz="4.60e-06"/>
    </inertial>
  </link>
  <!--covers are always with sensors-->
  <link name="base_0_ah_link_11_cover">
    <visual>
      <geometry>
        <mesh filename="package://xela_models/mesh/allegro/link_1_cover.stl"/>
      </geometry>
      <material name="red"/>
    </visual>
    <collision>
      <geometry>
        <mesh filename="package://xela_models/mesh/allegro/link_1_cover.stl"/>
      </geometry>
      <origin rpy="0 0 0" xyz="0 0 0"/>
    </collision>
  </link>
  <joint name="base_0_ah_link_11_cover_joint" type="fixed">
    <origin rpy="0.0 0.0 0.0" xyz="0.0 0.0 0.0"/>
    <parent link="base_0_ah_link_11"/>
    <child link="base_0_ah_link_11_cover"/>
  </joint>
  <joint name="base_x_taxel_0_11_4x4_fixed" type="fixed">
    <origin rpy="0.0 -1.5707963267948966 3.141592653589793" xyz="0.0108 0.012 0.033"/>
    <parent link="base_0_ah_link_11"/>
    <child link="base_x_taxel_0_11_4x4_link"/>
  </joint>
  <link name="base_x_taxel_0_11_4x4_link">
    <collision>
      <origin rpy="0 0 0" xyz="0 0 0"/>
      <geometry>
        <mesh filename="package://xela_models/mesh/4x4.stl"/>
      </geometry>
    </collision>
    <visual>
      <origin rpy="0 0 0" xyz="0 0 0"/>
      <geometry>
        <mesh filename="package://xela_models/mesh/4x4.stl"/>
      </geometry>
      <material name="red"/>
    </visual>
  </link>
  <gazebo reference="base_x_taxel_0_11_4x4_link">
    <material>Gazebo/Green</material>
  </gazebo>
  <joint name="base_x_taxel_0_10_4x4_fixed" type="fixed">
    <origin rpy="0.0 1.5707963267948966 0.0" xyz="0.0108 -0.012 0.021"/>
    <parent link="base_0_ah_link_11"/>
    <child link="base_x_taxel_0_10_4x4_link"/>
  </joint>
  <link name="base_x_taxel_0_10_4x4_link">
    <collision>
      <origin rpy="0 0 0" xyz="0 0 0"/>
      <geometry>
        <mesh filename="package://xela_models/mesh/4x4.stl"/>
      </geometry>
    </collision>
    <visual>
      <origin rpy="0 0 0" xyz="0 0 0"/>
      <geometry>
        <mesh filename="package://xela_models/mesh/4x4.stl"/>
      </geometry>
      <material name="red"/>
    </visual>
  </link>
  <gazebo reference="base_x_taxel_0_10_4x4_link">
    <material>Gazebo/Green</material>
  </gazebo>
  <joint name="ah_joint11" type="revolute">
    <limit effort="15" lower="-0.19599999999999998" upper="1.6099999999999999" velocity="7"/>
    <axis xyz="0 1 0"/>
    <parent link="base_0_ah_link_10"/>
    <child link="base_0_ah_link_11"/>
    <origin xyz="0 0 0.0204"/>
    <!-- New height on fingers -->
  </joint>
  <link name="base_0_ah_link_12">
    <visual>
      <geometry>
        <mesh filename="package://xela_models/mesh/allegro/link_2.0.stl"/>
      </geometry>
      <material name="black"/>
    </visual>
    <collision>
      <geometry>
        <box size="0.0196 0.0275 0.054"/>
      </geometry>
      <origin rpy="0 0 0" xyz="0 0 0.027"/>
    </collision>
    <!--covers are always with sensors-->
    <inertial>
      <mass value="0.0447"/>
      <origin rpy="0 0 0" xyz="0 0 0"/>
      <inertia ixx="3.80e-07" ixy="0.0" ixz="7.15e-09" iyy="2.26e-07" iyz="1.34e-09" izz="1.86e-07"/>
    </inertial>
  </link>
  <link name="base_0_ah_link_12_cover">
    <visual>
      <geometry>
        <mesh filename="package://xela_models/mesh/allegro/link_2_cover.stl"/>
      </geometry>
      <material name="red"/>
    </visual>
    <collision>
      <geometry>
        <mesh filename="package://xela_models/mesh/allegro/link_2_cover.stl"/>
      </geometry>
      <origin rpy="0 0 0" xyz="0 0 0"/>
    </collision>
  </link>
  <joint name="base_0_ah_link_12_cover_joint" type="fixed">
    <origin rpy="0.0 0.0 0.0" xyz="0.0 0.0 0.0"/>
    <parent link="base_0_ah_link_12"/>
    <child link="base_0_ah_link_12_cover"/>
  </joint>
  <joint name="base_x_taxel_0_12_4x4_fixed" type="fixed">
    <origin rpy="0.0 1.5707963267948966 0.0" xyz="0.01 -0.012 0.0445"/>
    <parent link="base_0_ah_link_12"/>
    <child link="base_x_taxel_0_12_4x4_link"/>
  </joint>
  <link name="base_x_taxel_0_12_4x4_link">
    <collision>
      <origin rpy="0 0 0" xyz="0 0 0"/>
      <geometry>
        <mesh filename="package://xela_models/mesh/4x4.stl"/>
      </geometry>
    </collision>
    <visual>
      <origin rpy="0 0 0" xyz="0 0 0"/>
      <geometry>
        <mesh filename="package://xela_models/mesh/4x4.stl"/>
      </geometry>
      <material name="red"/>
    </visual>
  </link>
  <gazebo reference="base_x_taxel_0_12_4x4_link">
    <material>Gazebo/Green</material>
  </gazebo>
  <joint name="ah_joint12" type="revolute">
    <axis xyz="0 1 0"/>
    <limit effort="15" lower="-0.17400000000000002" upper="1.7089999999999999" velocity="7"/>
    <parent link="base_0_ah_link_11"/>
    <child link="base_0_ah_link_12"/>
    <origin xyz="0 0 0.054"/>
  </joint>
  <link name="base_0_ah_link_13">
    <visual>
      <geometry>
        <mesh filename="package://xela_models/mesh/allegro/link_3.0.STL"/>
      </geometry>
      <material name="black"/>
    </visual>
    <collision>
      <geometry>
        <box size="0.0196 0.0275 0.026399999999999996"/>
      </geometry>
      <origin rpy="0 0 0" xyz="0 0 0.013199999999999998"/>
    </collision>
    <inertial>
      <mass value="0.0404"/>
      <origin rpy="0 0 0" xyz="0 0 0"/>
      <inertia ixx="3.64e-06" ixy="0.0" ixz="0.0" iyy="3.33e-06" iyz="0.0" izz="1.92e-06"/>
    </inertial>
  </link>
  <joint name="ah_joint13" type="revolute">
    <axis xyz="0 1 0"/>
    <limit effort="15" lower="-0.227" upper="1.6179999999999999" velocity="7"/>
    <parent link="base_0_ah_link_12"/>
    <child link="base_0_ah_link_13"/>
    <origin xyz="0 0.0 0.0384"/>
  </joint>
  <joint name="base_x_taxel_0_13_aftc_fixed" type="fixed">
    <origin rpy="1.5707963267948966 0.0 1.5707963267948966" xyz="-0.013 0.0 0.016"/>
    <parent link="base_0_ah_link_13"/>
    <child link="base_x_taxel_0_13_aftc_link"/>
  </joint>
  <link name="base_x_taxel_0_13_aftc_link">
    <collision>
      <origin rpy="0 0 0" xyz="0 0 0"/>
      <geometry>
        <mesh filename="package://xela_models/mesh/ft_c.stl"/>
      </geometry>
    </collision>
    <visual>
      <origin rpy="0 0 0" xyz="0 0 0"/>
      <geometry>
        <mesh filename="package://xela_models/mesh/ft_c.stl" scale="0.93 0.93 0.93"/>
      </geometry>
      <material name="red"/>
    </visual>
  </link>
  <link name="base_0_ah_link_20">
    <visual>
      <geometry>
        <mesh filename="package://xela_models/mesh/allegro/link_0.0_ext.STL"/>
      </geometry>
      <material name="grey"/>
    </visual>
    <collision>
      <geometry>
        <box size="0.0196 0.0275 0.0164"/>
      </geometry>
      <origin rpy="0 0 0" xyz="0 0 0.011200000000000002"/>
    </collision>
    <inertial>
      <mass value="0.0127"/>
      <origin rpy="0 0 0" xyz="0 0 0"/>
      <inertia ixx="1.38e-07" ixy="1.27e-10" ixz="4.83e-09" iyy="6.83e-08" iyz="0.0" izz="1.16e-07"/>
    </inertial>
  </link>
  <joint name="ah_joint20" type="revolute">
    <axis xyz="0 0 1"/>
    <limit effort="15" lower="-0.47" upper="0.47" velocity="7"/>
    <parent link="base_0_palm_link"/>
    <child link="base_0_ah_link_20"/>
    <origin rpy="0.0 0 0" xyz="0 0 0.0007"/>
  </joint>
  <link name="base_0_ah_link_21">
    <visual>
      <geometry>
        <mesh filename="package://xela_models/mesh/allegro/link_1.0.stl"/>
      </geometry>
      <material name="black"/>
    </visual>
    <collision>
      <geometry>
        <box size="0.0196 0.0275 0.054"/>
      </geometry>
      <origin rpy="0 0 0" xyz="0 0 0.027"/>
    </collision>
    <inertial>
      <mass value="0.0809"/>
      <origin rpy="0 0 0" xyz="0 0 0"/>
      <inertia ixx="1.75e-05" ixy="0.0" ixz="5.66e-08" iyy="1.80e-05" iyz="0.0" izz="4.60e-06"/>
    </inertial>
  </link>
  <!--covers are always with sensors-->
  <link name="base_0_ah_link_21_cover">
    <visual>
      <geometry>
        <mesh filename="package://xela_models/mesh/allegro/link_1_cover.stl"/>
      </geometry>
      <material name="red"/>
    </visual>
    <collision>
      <geometry>
        <mesh filename="package://xela_models/mesh/allegro/link_1_cover.stl"/>
      </geometry>
      <origin rpy="0 0 0" xyz="0 0 0"/>
    </collision>
  </link>
  <joint name="base_0_ah_link_21_cover_joint" type="fixed">
    <origin rpy="0.0 0.0 0.0" xyz="0.0 0.0 0.0"/>
    <parent link="base_0_ah_link_21"/>
    <child link="base_0_ah_link_21_cover"/>
  </joint>
  <joint name="base_x_taxel_0_21_4x4_fixed" type="fixed">
    <origin rpy="0.0 -1.5707963267948966 3.141592653589793" xyz="0.0108 0.012 0.033"/>
    <parent link="base_0_ah_link_21"/>
    <child link="base_x_taxel_0_21_4x4_link"/>
  </joint>
  <link name="base_x_taxel_0_21_4x4_link">
    <collision>
      <origin rpy="0 0 0" xyz="0 0 0"/>
      <geometry>
        <mesh filename="package://xela_models/mesh/4x4.stl"/>
      </geometry>
    </collision>
    <visual>
      <origin rpy="0 0 0" xyz="0 0 0"/>
      <geometry>
        <mesh filename="package://xela_models/mesh/4x4.stl"/>
      </geometry>
      <material name="red"/>
    </visual>
  </link>
  <gazebo reference="base_x_taxel_0_21_4x4_link">
    <material>Gazebo/Green</material>
  </gazebo>
  <joint name="base_x_taxel_0_20_4x4_fixed" type="fixed">
    <origin rpy="0.0 1.5707963267948966 0.0" xyz="0.0108 -0.012 0.021"/>
    <parent link="base_0_ah_link_21"/>
    <child link="base_x_taxel_0_20_4x4_link"/>
  </joint>
  <link name="base_x_taxel_0_20_4x4_link">
    <collision>
      <origin rpy="0 0 0" xyz="0 0 0"/>
      <geometry>
        <mesh filename="package://xela_models/mesh/4x4.stl"/>
      </geometry>
    </collision>
    <visual>
      <origin rpy="0 0 0" xyz="0 0 0"/>
      <geometry>
        <mesh filename="package://xela_models/mesh/4x4.stl"/>
      </geometry>
      <material name="red"/>
    </visual>
  </link>
  <gazebo reference="base_x_taxel_0_20_4x4_link">
    <material>Gazebo/Green</material>
  </gazebo>
  <joint name="ah_joint21" type="revolute">
    <limit effort="15" lower="-0.19599999999999998" upper="1.6099999999999999" velocity="7"/>
    <axis xyz="0 1 0"/>
    <parent link="base_0_ah_link_20"/>
    <child link="base_0_ah_link_21"/>
    <origin xyz="0 0 0.0204"/>
    <!-- New height on fingers -->
  </joint>
  <link name="base_0_ah_link_22">
    <visual>
      <geometry>
        <mesh filename="package://xela_models/mesh/allegro/link_2.0.stl"/>
      </geometry>
      <material name="black"/>
    </visual>
    <collision>
      <geometry>
        <box size="0.0196 0.0275 0.054"/>
      </geometry>
      <origin rpy="0 0 0" xyz="0 0 0.027"/>
    </collision>
    <!--covers are always with sensors-->
    <inertial>
      <mass value="0.0447"/>
      <origin rpy="0 0 0" xyz="0 0 0"/>
      <inertia ixx="3.80e-07" ixy="0.0" ixz="7.15e-09" iyy="2.26e-07" iyz="1.34e-09" izz="1.86e-07"/>
    </inertial>
  </link>
  <link name="base_0_ah_link_22_cover">
    <visual>
      <geometry>
        <mesh filename="package://xela_models/mesh/allegro/link_2_cover.stl"/>
      </geometry>
      <material name="red"/>
    </visual>
    <collision>
      <geometry>
        <mesh filename="package://xela_models/mesh/allegro/link_2_cover.stl"/>
      </geometry>
      <origin rpy="0 0 0" xyz="0 0 0"/>
    </collision>
  </link>
  <joint name="base_0_ah_link_22_cover_joint" type="fixed">
    <origin rpy="0.0 0.0 0.0" xyz="0.0 0.0 0.0"/>
    <parent link="base_0_ah_link_22"/>
    <child link="base_0_ah_link_22_cover"/>
  </joint>
  <joint name="base_x_taxel_0_22_4x4_fixed" type="fixed">
    <origin rpy="0.0 1.5707963267948966 0.0" xyz="0.01 -0.012 0.0445"/>
    <parent link="base_0_ah_link_22"/>
    <child link="base_x_taxel_0_22_4x4_link"/>
  </joint>
  <link name="base_x_taxel_0_22_4x4_link">
    <collision>
      <origin rpy="0 0 0" xyz="0 0 0"/>
      <geometry>
        <mesh filename="package://xela_models/mesh/4x4.stl"/>
      </geometry>
    </collision>
    <visual>
      <origin rpy="0 0 0" xyz="0 0 0"/>
      <geometry>
        <mesh filename="package://xela_models/mesh/4x4.stl"/>
      </geometry>
      <material name="red"/>
    </visual>
  </link>
  <gazebo reference="base_x_taxel_0_22_4x4_link">
    <material>Gazebo/Green</material>
  </gazebo>
  <joint name="ah_joint22" type="revolute">
    <axis xyz="0 1 0"/>
    <limit effort="15" lower="-0.17400000000000002" upper="1.7089999999999999" velocity="7"/>
    <parent link="base_0_ah_link_21"/>
    <child link="base_0_ah_link_22"/>
    <origin xyz="0 0 0.054"/>
  </joint>
  <link name="base_0_ah_link_23">
    <visual>
      <geometry>
        <mesh filename="package://xela_models/mesh/allegro/link_3.0.STL"/>
      </geometry>
      <material name="black"/>
    </visual>
    <collision>
      <geometry>
        <box size="0.0196 0.0275 0.026399999999999996"/>
      </geometry>
      <origin rpy="0 0 0" xyz="0 0 0.013199999999999998"/>
    </collision>
    <inertial>
      <mass value="0.0404"/>
      <origin rpy="0 0 0" xyz="0 0 0"/>
      <inertia ixx="3.64e-06" ixy="0.0" ixz="0.0" iyy="3.33e-06" iyz="0.0" izz="1.92e-06"/>
    </inertial>
  </link>
  <joint name="ah_joint23" type="revolute">
    <axis xyz="0 1 0"/>
    <limit effort="15" lower="-0.227" upper="1.6179999999999999" velocity="7"/>
    <parent link="base_0_ah_link_22"/>
    <child link="base_0_ah_link_23"/>
    <origin xyz="0 0.0 0.0384"/>
  </joint>
  <joint name="base_x_taxel_0_23_aftc_fixed" type="fixed">
    <origin rpy="1.5707963267948966 0.0 1.5707963267948966" xyz="-0.013 0.0 0.016"/>
    <parent link="base_0_ah_link_23"/>
    <child link="base_x_taxel_0_23_aftc_link"/>
  </joint>
  <link name="base_x_taxel_0_23_aftc_link">
    <collision>
      <origin rpy="0 0 0" xyz="0 0 0"/>
      <geometry>
        <mesh filename="package://xela_models/mesh/ft_c.stl"/>
      </geometry>
    </collision>
    <visual>
      <origin rpy="0 0 0" xyz="0 0 0"/>
      <geometry>
        <mesh filename="package://xela_models/mesh/ft_c.stl" scale="0.93 0.93 0.93"/>
      </geometry>
      <material name="red"/>
    </visual>
  </link>
  <link name="base_0_ah_link_30">
    <visual>
      <geometry>
        <mesh filename="package://xela_models/mesh/allegro/link_0.0_ext.STL"/>
      </geometry>
      <material name="grey"/>
    </visual>
    <collision>
      <geometry>
        <box size="0.0196 0.0275 0.0164"/>
      </geometry>
      <origin rpy="0 0 0" xyz="0 0 0.011200000000000002"/>
    </collision>
    <inertial>
      <mass value="0.0127"/>
      <origin rpy="0 0 0" xyz="0 0 0"/>
      <inertia ixx="1.38e-07" ixy="1.27e-10" ixz="4.83e-09" iyy="6.83e-08" iyz="0.0" izz="1.16e-07"/>
    </inertial>
  </link>
  <joint name="ah_joint30" type="revolute">
    <axis xyz="0 0 1"/>
    <limit effort="15" lower="-0.47" upper="0.47" velocity="7"/>
    <parent link="base_0_palm_link"/>
    <child link="base_0_ah_link_30"/>
    <origin rpy="0.08726646259971647 0 0" xyz="0 -0.0435 -0.001542"/>
  </joint>
  <link name="base_0_ah_link_31">
    <visual>
      <geometry>
        <mesh filename="package://xela_models/mesh/allegro/link_1.0.stl"/>
      </geometry>
      <material name="black"/>
    </visual>
    <collision>
      <geometry>
        <box size="0.0196 0.0275 0.054"/>
      </geometry>
      <origin rpy="0 0 0" xyz="0 0 0.027"/>
    </collision>
    <inertial>
      <mass value="0.0809"/>
      <origin rpy="0 0 0" xyz="0 0 0"/>
      <inertia ixx="1.75e-05" ixy="0.0" ixz="5.66e-08" iyy="1.80e-05" iyz="0.0" izz="4.60e-06"/>
    </inertial>
  </link>
  <!--covers are always with sensors-->
  <link name="base_0_ah_link_31_cover">
    <visual>
      <geometry>
        <mesh filename="package://xela_models/mesh/allegro/link_1_cover.stl"/>
      </geometry>
      <material name="red"/>
    </visual>
    <collision>
      <geometry>
        <mesh filename="package://xela_models/mesh/allegro/link_1_cover.stl"/>
      </geometry>
      <origin rpy="0 0 0" xyz="0 0 0"/>
    </collision>
  </link>
  <joint name="base_0_ah_link_31_cover_joint" type="fixed">
    <origin rpy="0.0 0.0 0.0" xyz="0.0 0.0 0.0"/>
    <parent link="base_0_ah_link_31"/>
    <child link="base_0_ah_link_31_cover"/>
  </joint>
  <joint name="base_x_taxel_0_31_4x4_fixed" type="fixed">
    <origin rpy="0.0 -1.5707963267948966 3.141592653589793" xyz="0.0108 0.012 0.033"/>
    <parent link="base_0_ah_link_31"/>
    <child link="base_x_taxel_0_31_4x4_link"/>
  </joint>
  <link name="base_x_taxel_0_31_4x4_link">
    <collision>
      <origin rpy="0 0 0" xyz="0 0 0"/>
      <geometry>
        <mesh filename="package://xela_models/mesh/4x4.stl"/>
      </geometry>
    </collision>
    <visual>
      <origin rpy="0 0 0" xyz="0 0 0"/>
      <geometry>
        <mesh filename="package://xela_models/mesh/4x4.stl"/>
      </geometry>
      <material name="red"/>
    </visual>
  </link>
  <gazebo reference="base_x_taxel_0_31_4x4_link">
    <material>Gazebo/Green</material>
  </gazebo>
  <joint name="base_x_taxel_0_30_4x4_fixed" type="fixed">
    <origin rpy="0.0 1.5707963267948966 0.0" xyz="0.0108 -0.012 0.021"/>
    <parent link="base_0_ah_link_31"/>
    <child link="base_x_taxel_0_30_4x4_link"/>
  </joint>
  <link name="base_x_taxel_0_30_4x4_link">
    <collision>
      <origin rpy="0 0 0" xyz="0 0 0"/>
      <geometry>
        <mesh filename="package://xela_models/mesh/4x4.stl"/>
      </geometry>
    </collision>
    <visual>
      <origin rpy="0 0 0" xyz="0 0 0"/>
      <geometry>
        <mesh filename="package://xela_models/mesh/4x4.stl"/>
      </geometry>
      <material name="red"/>
    </visual>
  </link>
  <gazebo reference="base_x_taxel_0_30_4x4_link">
    <material>Gazebo/Green</material>
  </gazebo>
  <joint name="ah_joint31" type="revolute">
    <limit effort="15" lower="-0.19599999999999998" upper="1.6099999999999999" velocity="7"/>
    <axis xyz="0 1 0"/>
    <parent link="base_0_ah_link_30"/>
    <child link="base_0_ah_link_31"/>
    <origin xyz="0 0 0.0204"/>
    <!-- New height on fingers -->
  </joint>
  <link name="base_0_ah_link_32">
    <visual>
      <geometry>
        <mesh filename="package://xela_models/mesh/allegro/link_2.0.stl"/>
      </geometry>
      <material name="black"/>
    </visual>
    <collision>
      <geometry>
        <box size="0.0196 0.0275 0.054"/>
      </geometry>
      <origin rpy="0 0 0" xyz="0 0 0.027"/>
    </collision>
    <!--covers are always with sensors-->
    <inertial>
      <mass value="0.0447"/>
      <origin rpy="0 0 0" xyz="0 0 0"/>
      <inertia ixx="3.80e-07" ixy="0.0" ixz="7.15e-09" iyy="2.26e-07" iyz="1.34e-09" izz="1.86e-07"/>
    </inertial>
  </link>
  <link name="base_0_ah_link_32_cover">
    <visual>
      <geometry>
        <mesh filename="package://xela_models/mesh/allegro/link_2_cover.stl"/>
      </geometry>
      <material name="red"/>
    </visual>
    <collision>
      <geometry>
        <mesh filename="package://xela_models/mesh/allegro/link_2_cover.stl"/>
      </geometry>
      <origin rpy="0 0 0" xyz="0 0 0"/>
    </collision>
  </link>
  <joint name="base_0_ah_link_32_cover_joint" type="fixed">
    <origin rpy="0.0 0.0 0.0" xyz="0.0 0.0 0.0"/>
    <parent link="base_0_ah_link_32"/>
    <child link="base_0_ah_link_32_cover"/>
  </joint>
  <joint name="base_x_taxel_0_32_4x4_fixed" type="fixed">
    <origin rpy="0.0 1.5707963267948966 0.0" xyz="0.01 -0.012 0.0445"/>
    <parent link="base_0_ah_link_32"/>
    <child link="base_x_taxel_0_32_4x4_link"/>
  </joint>
  <link name="base_x_taxel_0_32_4x4_link">
    <collision>
      <origin rpy="0 0 0" xyz="0 0 0"/>
      <geometry>
        <mesh filename="package://xela_models/mesh/4x4.stl"/>
      </geometry>
    </collision>
    <visual>
      <origin rpy="0 0 0" xyz="0 0 0"/>
      <geometry>
        <mesh filename="package://xela_models/mesh/4x4.stl"/>
      </geometry>
      <material name="red"/>
    </visual>
  </link>
  <gazebo reference="base_x_taxel_0_32_4x4_link">
    <material>Gazebo/Green</material>
  </gazebo>
  <joint name="ah_joint32" type="revolute">
    <axis xyz="0 1 0"/>
    <limit effort="15" lower="-0.17400000000000002" upper="1.7089999999999999" velocity="7"/>
    <parent link="base_0_ah_link_31"/>
    <child link="base_0_ah_link_32"/>
    <origin xyz="0 0 0.054"/>
  </joint>
  <link name="base_0_ah_link_33">
    <visual>
      <geometry>
        <mesh filename="package://xela_models/mesh/allegro/link_3.0.STL"/>
      </geometry>
      <material name="black"/>
    </visual>
    <collision>
      <geometry>
        <box size="0.0196 0.0275 0.026399999999999996"/>
      </geometry>
      <origin rpy="0 0 0" xyz="0 0 0.013199999999999998"/>
    </collision>
    <inertial>
      <mass value="0.0404"/>
      <origin rpy="0 0 0" xyz="0 0 0"/>
      <inertia ixx="3.64e-06" ixy="0.0" ixz="0.0" iyy="3.33e-06" iyz="0.0" izz="1.92e-06"/>
    </inertial>
  </link>
  <joint name="ah_joint33" type="revolute">
    <axis xyz="0 1 0"/>
    <limit effort="15" lower="-0.227" upper="1.6179999999999999" velocity="7"/>
    <parent link="base_0_ah_link_32"/>
    <child link="base_0_ah_link_33"/>
    <origin xyz="0 0.0 0.0384"/>
  </joint>
  <joint name="base_x_taxel_0_33_aftc_fixed" type="fixed">
    <origin rpy="1.5707963267948966 0.0 1.5707963267948966" xyz="-0.013 0.0 0.016"/>
    <parent link="base_0_ah_link_33"/>
    <child link="base_x_taxel_0_33_aftc_link"/>
  </joint>
  <link name="base_x_taxel_0_33_aftc_link">
    <collision>
      <origin rpy="0 0 0" xyz="0 0 0"/>
      <geometry>
        <mesh filename="package://xela_models/mesh/ft_c.stl"/>
      </geometry>
    </collision>
    <visual>
      <origin rpy="0 0 0" xyz="0 0 0"/>
      <geometry>
        <mesh filename="package://xela_models/mesh/ft_c.stl" scale="0.93 0.93 0.93"/>
      </geometry>
      <material name="red"/>
    </visual>
  </link>
</robot>
